# 예외처리(Exception handling)

- 컴파일 에러 : 컴파일 시 발생
- 런타임 에러 : 실행 시 발생하는 에러
- 논리적 에러 : 실행은 되지만, 의도와 다르게 동작


런타임 에러를 방지하기 위해서는 프로그램의 실행도중 발생할 수 있는 모든 경우의 수를 고려해 이에 대한 대비를 하는 것이 필요하다.

자바에서는 실행 시 발생할 수 있는 프로그램 오류를 에러와 예외 두가지로 구분한다.

- 에러 : 프로그램 코드에 의해서 수습될 수 없는 심각한 오류
- 예외 : 프로그램 코드에 의해서 수습될 수 있는 다소 미약한 오류


에러는 메모리 부족, 스택오버플로우와 같이 일반 발생하면 복구할 수 없는 심각한 오류이고, 예외는 발생하더라도 수습할 수 있는 비교적 덜 심각한 것이다.

# 예외클래스 계층구조

자바에서는 실행 시 발생할 수 있는 오류를 클래스로 정의했다. 모든 클래스의 조상은 Object클래스이므로 Exception과 Error클래스 역시 Object 클래스의 자손들이다.

![image](https://user-images.githubusercontent.com/65898555/179635052-55727488-07cc-45b4-9f51-e2a338302b38.png)

![image](https://user-images.githubusercontent.com/65898555/179635109-8ef09fbf-92b5-4147-8025-20fa3e889d5f.png)

모든 예외의 최고 조상은 Exception클래스이다.

예외 클래스는 두그룹으로 나뉠 수 있다.

1. Exception 클래스와 그 자손들(RuntimeException과 자손들 제외) : 사용자의 실수와 같은 외적인 요인에 의해 발생하는 예외
2. RuntimeException 클래스와 그 자손들 : 프로그래머의 실수로 발생하는 예외

RuntimeException클래스들은 주로 프로그래머의 실수에 의해 발생될 수 있는 예외들로 자바의 프로그래밍 요소들과 관계기 깊다.

예를 들면 배열의 범위를 벗어나는(ArrayIndexOutOfBoundsException), 값이 null인 참조변수의 멤버를 호출하려 하는경우(NullPointerException), 클래스간 형변환이 잘못된 경우(ClassCastException), 정수를 
0으로 나누려고 하는 경우(ArtihmeticException) 경우에 발생한다.


# 예외 처리하기 try-catch문

예외처리란 프로그램 실행 시 발생할 수 있는 예기치 못한 예외의 발생에 대비한 코드를 작성하는 것이다. 예외처리의 목적은 예외의 발생으로 인한 실행 중인 프로그램의 갑작스런 비정상 종료를 
막고, 정상적인 실행상태를 유지하는 것이다.

발생한 예외를 처리하지 못하면, 프로그램은 비정상적으로 종료되고, 처리되지 못한 예외는 JVM의 예외처리기가 받아서 예외의 원인을 화면에 출력한다.

```java
try{
    //예외가 발생할 가능성이 있는 문장
} catch(Exception e1){

} catch(Exception e2){

} catch(Exception e3){

}
```
하나의 try블록 다음에는 여러 종류의 예외를 처리할 수 있도록 하나 이상의 catch블록이 올 수 있다. 이 중 발생한 예외의 종류와 일치하는 단 한개의 catch 블록만 실행된다.
발생한 예외의 종류와 일치하는 catch블록이 없으면 예외는 처리되지 않는다.

```java
class ExceptionEx1 {
	public static void main(String[] args) 
   {
		try  {
			try	{	} catch (Exception e)	{ }
		} catch (Exception e)	{
			try	{	} catch (Exception e) { }	// 에러. 변수 e가 중복 선언되었다.
		} // try-catch의 끝

		try  {

		} catch (Exception e)	{

		} // try-catch의 끝
	}	// main메서드의 끝
}
```
하나의 메서드 내에 여러개의 try-catch문이 사용될 수 있다. try블럭 또는 catch블럭에 또 다른 try-catch문이 포함될 수 있다. catch블럭 내에서도 예외가 발생할 수 있기 때문이다.


```java
class ExceptionEx3 {
	public static void main(String args[]) {
		int number = 100;
		int result = 0;

		for(int i=0; i < 10; i++) {
			try {
				result = number / (int)(Math.random() * 10);
				System.out.println(result);
			} catch (ArithmeticException e)	{
				System.out.println("0");	
			} // try-catchÀÇ ³¡
		} // forÀÇ ³¡
	} 
}
```
```
16
20
11
0
25
100
25
33
14
12
```
위 예제에서는 예외처리를 해서 프로그램이 종료되지 않는다

# try-catch문에서의 흐름

try블록 내에서 예외가 발생한 경우 발생한 예외와 일치한 catch 블럭이 있는지 확인 후 일치하는 catch블럭을 찾으면 그 catch블럭내의 문장들을 수행하고 전체 try-catch문을 빠져 나온다.
그 후 다음 문장을 수행한다. 만일 일치하는 catch블럭을 차지 못하면 예외 처리를 못한다.

try블럭 내에서 예외가 발생하지 않은 경우 catch블럭을 거치지 않고 전체 try-catch문을 빠져나가서 수행을 계속한다.

# 예외 발생과 catch블럭

```java
class ExceptionEx6 {
	public static void main(String args[]) {
		System.out.println(1);			
		System.out.println(2);
		try {
			System.out.println(3);
			System.out.println(0/0);
			System.out.println(4); 	// 실행되지 않는다.
		} catch (Exception e)	{	// ArithmeticException대신 Exception을 사용.
			System.out.println(5);
		}	// try-catch의 끝
		System.out.println(6);
	}	// main메서드의 끝
}
```
```java
class ExceptionEx7 {
	public static void main(String args[]) {
		System.out.println(1);			
		System.out.println(2);
		try {
			System.out.println(3);
			System.out.println(0/0);
			System.out.println(4); 		// 실행되지 않는다.
		} catch (ArithmeticException ae)	{
			if (ae instanceof ArithmeticException) 
				System.out.println("true");	
			System.out.println("ArithmeticException");
		} catch (Exception e)	{ // ArithmeticException을 제외한 모든 예외 처리
			System.out.println("Exception");
		}	// try-catch의 끝
		System.out.println(6);
	}	// main메서드의 끝
}
```
위 예제처럼 try-catch문 마지막에 Exception클래스 타입의 참조변수를 선언한 catch블럭을 사용하면, 어떤 종류의 예외가 발생하더라도 이 catch블럭에 의해 처리되도록 할 수 있다.

# printStackTrace(), getMessage()

예외가 발생했을 때 생성되는 예외 클래스의 인스턴스에는 발생한 예외에 대한 정보가 담겨있으며, getMessage()와 pringStackTrace()를 통해서 이 정보들을 얻을 수 있다.
catch블럭의 괄호에 선언된 참조변수를 통해 이 인스턴스에 접근할 수 있다.

- printStackTrace() : 예외발생 당시의 호출스택에 있었던 메서드의 정보와 예외 메시지를 화면에 출력
- getMessage() : 발생한 예외클래스의 인스턴스에 저장된 메시지를 얻을 수 있다.

```java
class ExceptionEx8 {
	public static void main(String args[]) {
		System.out.println(1);			
		System.out.println(2);
		try {
			System.out.println(3);
			System.out.println(0/0); // 예외발생!!!
			System.out.println(4); 	 // 실행되지 않는다.
		} catch (ArithmeticException ae)	{
			ae.printStackTrace();
			System.out.println("예외메시지 : " + ae.getMessage());
		}	// try-catch의 끝
		System.out.println(6);
	}	// main메서드의 끝
}
```
```
1
2
3
java.lang.ArithmeticException: / by zero
    at ExceptionEx8.main(ExceptionEx8.java:7)
예외메시지 : / by zero
6
```
위 예제에서는 ArithmeticException인스턴스의 printStackTrace()를 사용해서, 호출스택(call stack)에 대한 정보와 예외 메시지를 출력하였다.


# 멀티 catch 블럭

jdk1.7부터 여러 catch블럭을 '|'기호를 이용해서, 하나의 catch블럭으로 합칠 수 있게 되었다. 이를 멀티 catch 블럭이라고 한다.

```java
try{

} catch(ExceptionA e1){
    e1.printStackTrace();
} catch(ExceptionB e2){
    e2.printStackTrace();
}
```
```java
try{

} catch(ExceptionA | ExceptioB e){
    e.printStackTrace();
}
```
만일 멀티 catch 블럭의 '|'기호로 연결된 예외 클래스가 조상과 자손의 관계에 있다면 컴파일 에러가 발생한다.

이유는 두 예외 클래스가 조상과 자손의 관게에 있다면, 그냥 조상 클래스 하나만 적어주면 똑같기 때문이다. 즉 불필요한 코드는 제거하라는 의미에서 에러가 발생하는 것이다.

```java
try{
    
} catch(ExceptionA | ExceptionB e){
    e.methodA(); // error. ExceptionA에 선언된 methodA 호출불가
    
    if(e instanceof ExceptionA){
        ExceptionA e1 = (ExceptionA)e;
	e1.methodA(); // ok. 
    }else{
    
    }
    
    e.printStackTrace();
}
```
멀티 catch는 하나의 catch블럭으로 여러 예외를 처리하는 것이기 때문에, 발생한 예외를 멀티 catch블럭으로 처리하게 되었을 때, 멀티 catch블럭 내에서는 실제로 어떤 예외가 발생한 것인지
알 수 없다. 그래서 참조변수 e로 멀티 catch블럭에 '|'기호로 연결된 예외 클래스들의 공통 분모인 조상 예외 클래스에 선언된 멤버만 사용가능하다.

필요다하면 instanceof로 어떤 예외가 발생한 것인지 확인하고 개별적으로 처리할 수 있다. 그러나 이렇게까지 해가면서 catch블럭을 합칠 일은 거의 없다.

멀티 catch블럭에 선언되 참조변수 e는 상수이므로 값을 변경할 수 없다는 제약이 있는데, 이것은 여러 catch블럭이 하나의 참조변수를 공유하기 때문에 생기는 제약으로 실제로 참조변수의 값을 바꿀 일은 없을 것이다.

# 예외 발생시키기

1. 먼저 연산자 new를 이용해 발생시키려는 예외 클래스의 객체를 만든다음. ex) Exception e = new Exception("고의로 발생");
2. 키워드 throw를 이용해 예외를 발생 ex) throw e;

```java
class ExceptionEx9 {
	public static void main(String args[]) {
		try {
			Exception e = new Exception("고의로 발생시켰음.");
			throw e;	 // 예외를 발생시킴
		//  throw new Exception("고의로 발생시켰음.");  

		} catch (Exception e)	{
			System.out.println("에러 메시지 : " + e.getMessage());
		     e.printStackTrace();
		}
		System.out.println("프로그램이 정상 종료되었음.");
	}
}
```
```
에러 메시지 : 고의로 발생시켰음.
java.lang.Exception: 고의로 발생시켰음.
    at ExceptionEx9.main(ExceptionEx9.java:4)
프로그램이 정상 종료되었음.
```
Exception 인스턴스 생성 시, 생성자에 String을 넣어 주면, 이 String이 Exception 인스턴스에 메시지로 저장된다. 이 메시지는 getMessage를 이용해 얻을 수 있다.

```java
class ExceptionEx10 {
	public static void main(String[] args) {
		throw new Exception();		// ExceptionÀ» °íÀÇ·Î ¹ß»ý½ÃÅ²´Ù.
	}
}
```
위 경우에 컴파일 오류가 발생한다. Exception클래스들이 발생할 가능성이 있는 문장에 대해 예외처리를 해주지 않으면 컴파일이 않된다.

```java
class ExceptionEx11 {
	public static void main(String[] args) {
		throw new RuntimeException();	// RuntimeExceptionÀ» °íÀÇ·Î ¹ß»ý½ÃÅ²´Ù.
	}
}
```
위 예제는 컴파일이 된다. 그러나 실행하면 RuntimeException이 발생하며 비정상적으로 종료된다.

RuntimException 클래스와 그 자손들은 해당하는 예외는 프로그래머에 의해 실수로 발생하는 것들이기 때문에 예외처리를 강제하지 않는다.

이처럼 컴파일러가 예외처리를 확인하지 않는 RuntimException클래스들은 unchekced 예외라고 부른다

예외처리를 확인하는 Exception클래스들은 checked예외라고 부른다.



# 메서드에 예외 선언하기

메서드에 예외를 선언하려면 메서드의 선언부에 키워드 throws를 사용해서 메서드 내에서 발생할 수 있는 예외를 적어주기만 하면 된다.

```java
void method() thorws Exception1, Exception2, ... ExceptionN{

}
```

```java
void method() throws Exception{

}
```
위 코드처럼 예외를 선언하면 모든 예외의 최고조상인 Exception 클래스를 메서드에 선언하면, 이 메서드는 모든 종류의 예외가 발생할 가능성이 있다는 뜻이다.

메서드의 선언부에 예외를 선언함으로서 메서드를 사용하려는 사람이 메서드의 선언부를 보았을 때, 이 메서드를 사용하기 위해서는 어떠한 예외들이 처리되어져야 하는지 쉽게 알 수 있다.

자바에서는 메서드를 작성 시 메서드 내에서 발생할 가능성이 있는 예외를 메서드의 선언부에 명시하여 이 메서드를 사용하는 쪽에서는 이에 대한 처리를 하도록 강요하기 때문에, 프로그래머들의 짐을 덜어 주는 것을 물론이고 보다 견고한 프로그램 코드를 작성할 수 있도록 도와준다.

메서드 예외를 선언할 때 일반적으로 RuntimeException 클래스들은 적지 않는다. 이 들을 메서드 선언부의 throws에 선언하다고 해서 문제가 되지는 않지만, 보통 반드시 처리해주어야 하는 예외들만 선언한다.

```java
class ExceptionEx12 {
	public static void main(String[] args) throws Exception {
		method1();	 // 같은 클래스내의 static멤버이므로 객체생성없이 직접 호출가능.
  	}	// main메서드의 끝

	static void method1() throws Exception {
		method2();
	}	// method1의 끝

	static void method2() throws Exception {
		throw new Exception();
	}	// method2의 끝
}
```
예외를 메서드의 throws에 명시하는 것은 예외를 처리하는 것이 아니라, 자신(예외가 발생할 가능성이 있는 메서드)을 호출한 메서드에게 예외를 전달하여 예외처리를 떠맡기는 것이다. 예외를 전달받은 메서드가 또다시 자신을 호출한 메서드에게 전달할 수 있으며, 이런 식으로 계속 호출스택에 있는 메서드들을 따라 전달되다가 제일 마지막에 있는 main메서드에서도 예외가 처리되지 않으면, main메서드마저 종료되어 프로그램 전체가 종료된다.

위 코드를 통해 다음과 같은 사실을 알 수 있다.

1. 예외가 발생했을 때 모두 3개의 메서드(main, method1, method2)가 호출스택에 있었으며,
2. 예외가 발생한 곳은 제일 윗줄에 있는 method2라는 것과
3. main메서드가 method1을 그리고 method1은 method2를 호출했다는 것을 알 수 있다.

method2에서 throw new Exception 문장에 의해 예외가 강제적으로 발생했으나 try-catch문으로 예외처리가 없어서, method2는 종료되면서 자신을 호출한 method1에게 넘겨준다.
method1역시 예외처리가 없어 종료되면서 main메서드에게 예외를 넘긴다. 그러나 main메서드조차 예외처리가 없어 main메서드가 종료되어 프로그램이 예외로 인해 비정상적으로 종료되는 것이다.

이처럼 예외가 발생한 메서드에서 예외처리를 하지 않고 자신을 호출한 메서드에게 예외를 넘겨줄 수 있지만, 이것으로 예외가 처리된 것은 아니고 예외를 단순히 전달만 하는 것이다.
결국 어느 한 곳에서는 반드시 try-catch문으로 예외처리를 해야 한다.

```java
class ExceptionEx13 {
	public static void main(String[] args) {
		method1(); 	  // 같은 클래스내의 static멤버이므로 객체생성없이 직접 호출가능.
  	}	// main메서드의 끝

	static void method1() {
		try {
		     throw new Exception();
		} catch (Exception e) {
			System.out.println("method1메서드에서 예외가 처리되었습니다.");
			e.printStackTrace();
		}
	}	// method1의 끝
}
```
```java
class ExceptionEx14 {
	public static void main(String[] args) {
		try  {
				method1();		
		} catch (Exception e)	{
				System.out.println("main메서드에서 예외가 처리되었습니다.");
				e.printStackTrace();
		}
	}	// main메서드의 끝

	static void method1() throws Exception {
		throw new Exception();
	}	// method1()의 끝
} // class의 끝
```
13예제에서는 method1에서 예외처리를 했고, 14예제에서는 main에 예외를 전달하고 호출한 main메서드에서 try-cathc문을 이용해 예외처리를 했다.

13예제에서는 예외가 발생한 메서드 내에서 처리되면, 호출한 main메서드는 예외가 발생했다는 사실조차 모르게 된다.

이처럼 예외가 발생한 메서드에서 예외를 처리할 수도 있고, 예외가 발생한 메서드를 호출한 메서드에서 처리할수도 있고, 또는 두 메서드가 예외처리를 분담할 수도 있다.


```java
import java.io.*;

class ExceptionEx15 {
	public static void main(String[] args) {
        // command line에서 입력받은 값을 이름으로 갖는 파일을 생성한다.
		File f = createFile(args[0]);	
		System.out.println( f.getName() + " 파일이 성공적으로 생성되었습니다.");
	} // main메서드의 끝

	static File createFile(String fileName) {
		try {
			if (fileName==null || fileName.equals(""))
				throw new Exception("파일이름이 유효하지 않습니다.");
		} catch (Exception e) {
             // fileName이 부적절한 경우, 파일 이름을 '제목없음.txt'로 한다.
			fileName = "제목없음.txt";	 
		} finally {
			File f = new File(fileName); // File클래스의 객체를 만든다.
			createNewFile(f);		     // 생성된 객체를 이용해서 파일을 생성한다.
			return f;
		}
	}	// createFile메서드의 끝

	static void createNewFile(File f) {
		try {
			f.createNewFile();		// 파일을 생성한다.
		} catch(Exception e){ }
	}	// createNewFile메서드의 끝
} 
```
```java
import java.io.*;

class ExceptionEx16 {
	public static void main(String[] args) 
	{
		try {
			File f = createFile(args[0]);
			System.out.println( f.getName()+"파일이 성공적으로 생성되었습니다.");
		} catch (Exception e) {
			System.out.println(e.getMessage()+" 다시 입력해 주시기 바랍니다.");
		}
	}	// main메서드의 끝

	static File createFile(String fileName) throws Exception {
		if (fileName==null || fileName.equals(""))
			throw new Exception("파일이름이 유효하지 않습니다.");
		File f = new File(fileName);		//  File클래스의 객체를 만든다.
        // File객체의 createNewFile메서드를 이용해서 실제 파일을 생성한다.
		f.createNewFile();
		return f;		// 생성된 객체의 참조를 반환한다.
	}	// createFile메서드의 끝
}	// 클래스의 끝
```
예외가 발생한 메서드 내에서 자체적으로 처리해도 되는 것은 메서드 내에서 try-catch문을 사용해 처리하고, 16예제처럼 메서드에 호출 시 넘겨받아야 할 값을 다시 받아야 하는 경우(메서드에서 자체적으로 해결이 안되는 경우)에는 예외를 메서드에 선언해서, 호출한 메서드에서 처리해야 한다.



